Internal Server Error: /myadmin-encoded-target/staffs/salary-logs/
Traceback (most recent call last):
  File "C:\Users\hp\.virtualenvs\stylezbydee-MONumO1N\lib\site-packages\django\core\handlers\exception.py", line 55, in inner
    response = get_response(request)
  File "C:\Users\hp\.virtualenvs\stylezbydee-MONumO1N\lib\site-packages\django\core\handlers\base.py", line 197, in _get_response
    response = wrapped_callback(request, *callback_args, **callback_kwargs)
  File "C:\Users\hp\.virtualenvs\stylezbydee-MONumO1N\lib\site-packages\django\views\generic\base.py", line 104, in view
    return self.dispatch(request, *args, **kwargs)
  File "C:\Users\hp\.virtualenvs\stylezbydee-MONumO1N\lib\site-packages\django\views\generic\base.py", line 143, in dispatch
    return handler(request, *args, **kwargs)
  File "C:\Users\hp\.virtualenvs\stylezbydee-MONumO1N\lib\site-packages\django\views\generic\list.py", line 154, in get
    self.object_list = self.get_queryset()
  File "C:\Users\hp\Desktop\fiberswift\djangoprojects\stylezbydee\myadmin\staff.py", line 132, in get_queryset
    SalaryUtils.create_salary_logs()
  File "C:\Users\hp\Desktop\fiberswift\djangoprojects\stylezbydee\myadmin\utils.py", line 98, in create_salary_logs
    date_due = timezone.datetime(year, next_month, 25).date()
UnboundLocalError: local variable 'year' referenced before assignment
"GET /myadmin-encoded-target/staffs/salary-logs/ HTTP/1.1" 500 93897
Internal Server Error: /myadmin-encoded-target/staffs/add/
Traceback (most recent call last):
  File "C:\Users\hp\Desktop\fiberswift\djangoprojects\stylezbydee\myadmin\forms.py", line 135, in save
    staff.user = User.objects.get(account_id=user_id)
  File "C:\Users\hp\.virtualenvs\stylezbydee-MONumO1N\lib\site-packages\django\db\models\manager.py", line 87, in manager_method
    return getattr(self.get_queryset(), name)(*args, **kwargs)
  File "C:\Users\hp\.virtualenvs\stylezbydee-MONumO1N\lib\site-packages\django\db\models\query.py", line 637, in get
    raise self.model.DoesNotExist(
users.models.User.DoesNotExist: User matching query does not exist.

During handling of the above exception, another exception occurred:

Traceback (most recent call last):
  File "C:\Users\hp\.virtualenvs\stylezbydee-MONumO1N\lib\site-packages\django\core\handlers\exception.py", line 55, in inner
    response = get_response(request)
  File "C:\Users\hp\.virtualenvs\stylezbydee-MONumO1N\lib\site-packages\django\core\handlers\base.py", line 197, in _get_response
    response = wrapped_callback(request, *callback_args, **callback_kwargs)
  File "C:\Users\hp\.virtualenvs\stylezbydee-MONumO1N\lib\site-packages\django\views\generic\base.py", line 104, in view
    return self.dispatch(request, *args, **kwargs)
  File "C:\Users\hp\.virtualenvs\stylezbydee-MONumO1N\lib\site-packages\django\views\generic\base.py", line 143, in dispatch
    return handler(request, *args, **kwargs)
  File "C:\Users\hp\.virtualenvs\stylezbydee-MONumO1N\lib\site-packages\django\views\generic\edit.py", line 184, in post
    return super().post(request, *args, **kwargs)
  File "C:\Users\hp\.virtualenvs\stylezbydee-MONumO1N\lib\site-packages\django\views\generic\edit.py", line 153, in post
    return self.form_valid(form)
  File "C:\Users\hp\Desktop\fiberswift\djangoprojects\stylezbydee\myadmin\staff.py", line 40, in form_valid
    return super().form_valid(form)
  File "C:\Users\hp\.virtualenvs\stylezbydee-MONumO1N\lib\site-packages\django\views\generic\edit.py", line 135, in form_valid
    self.object = form.save()
  File "C:\Users\hp\Desktop\fiberswift\djangoprojects\stylezbydee\myadmin\forms.py", line 137, in save
    raise forms.ValidationError(
django.core.exceptions.ValidationError: ['No user found with User ID: 34534563545']
"POST /myadmin-encoded-target/staffs/add/ HTTP/1.1" 500 118294
